Workbook
Name biomass: Menus!$C$22:$C$24
Name cover: Menus!$C$19:$C$21
Name leak: Menus!$C$28:$C$30
Name logis: Menus!$C$48:$C$50
Name ner: Menus!$C$103:$C$105
Name opportunity: Menus!#REF!
Name opportunity: Menus!#REF!
Name size: Menus!$C$11:$C$13
Name soil: Menus!$C$25:$C$27
Name tenure: Menus!$B$34:$B$37
Name threat: Menus!$C$16:$C$18
Name topo: Menus!$C$2:$C$4
Name water: Menus!$C$55:$C$58
Name y_n: Menus!$C$38:$C$39

Sheet Menus
D1: Rating | E1: Weight
A2: Geospatial | B2: Topography | C2: Flat % | E2: 10
C3: Hilly % | E3: 5
C4: Mountainous % | E4: 1
B5: Location relative to protected areas ? | C5: Border | D5: y | E5: 8
D6: n | E6: 5
B8: JNR Boundaries | C8: Within political boundary | D8: y | E8: 8
D9: n | E9: 5
B11: Size (ha) | C11: > 150 000 | E11: 10
C12: 100 000 - 150 000 | E12: 5
C13: < 100 000 | E13: 2
B14: Landsat Tiles | C14: Adjacent: NO | E14: 2
C15: Above - Below: YES | E15: 4
A16: Forest metrics | B16: Deforestation threat | C16: High >25% perimeter | E16: 10
C17: Medium 10-25% | E17: 5
C18: Low <10% | E18: 2
B19: Forest cover | C19: High > 90% | E19: 10
C20: Medium 60-90% | E20: 7
C21: Low < 60% | E21: 2
B22: Biomass Carbon density | C22: High >150tCO2e/ha | E22: 10
C23: Medium100-150tCO2e/ha | E23: 7
C24: Low <100tCO2e/ha | E24: 3
B25: Soil Carbon | C25: High >150tCO2e/ha | E25: 10
C26: Medium100-150tCO2e/ha | E26: 7
C27: Low <100tCO2e/ha | E27: 3
A28: Leakage Risk | B28: Activity | C28: High | E28: 1
C29: Medium | E29: 5
C30: Low | E30: 10
B31: Market | C31: High | E31: 1
C32: Medium | E32: 5
C33: Low | E33: 10
A34: Tenure/Rights Holders | B34: Single Entity | E34: 8
B35: Multiple Entities | E35: 5
B36: Unclear | E36: 1
B37: Private title | E37: 6
B38: Title deed sound (if applicable) | C38: Y | E38: 10
C39: N | E39: 0
B40: Landowner/Rights Holder Invitation | C40: Y | E40: 10
C41: N | E41: 3
B42: Host country consent | C42: Y | E42: 5
...

Sheet How to
A8: Site
A9: Category | B9: Sub-category | D9: Rating* | E9: Score
A10: This section is completed using GIS, the more accurate and up to date datasets are available, the more inform the decision making will be. Getting data on boundaries of protected areas and even political boundaries can be problematic. Generally only flat lands get deforested and converted to agriculture. Beyond a 20° slope there is seldom deforestation, only degradation from charcoal. Deforestation on steep slopes only happens in places where there are deep soils on hills. A potential project area that is very hilly will most likely not be viable as it will be difficult to substantiate deforestation.
A11: Geospatial | B11: Topography | C11: Flat % | E11: =D11/100*Menus!E2 -> 0
C12: Hilly % | E12: =D12/100*Menus!E3 -> 0
C13: Mountainous % | E13: =D13/100*Menus!E4 -> 0
B14: Location relative to protected areas | C14: Border | E14: =IF(D14="Y",Menus!E5,Menus!E6) -> 5
B15: JNR Boundaries | C15: Within political boundary | E15: =IF(D15="Y",Menus!E8,Menus!E9) -> 5
B16: Size (ha) | E16: =IF(D16=Menus!C11,Menus!E11,IF(D16=Menus!C12,Menus!E12,Menus!E13)) -> 2
B17: Landsat Tiles | C17: Below | E17: =IF(D17="Y",Menus!E15,Menus!E14) -> 2
A18: Use data from in-country and global datasets, preferably from similar ecosystems. Deforestation threat and forest cover is assessed using remote sensing. Soil data from peer reviewed publications should be used with extreme caution as it is highly variable. It is important to remember that the deforested state does not have zero carbon, there is always a residual.
A19: Forest metrics | B19: Deforestation threat | E19: =IF(D19=Menus!C16,Menus!E16,IF('How to'!D19=Menus!C12,Menus!E12,Menus!E13)) -> 2
B20: Forest cover | E20: =IF(D20=Menus!C19,Menus!E19,IF(D20=Menus!C20,Menus!E20,Menus!E21)) -> 2
B21: Biomass Carbon density | E21: =IF(D21=Menus!C22,Menus!E22,IF('How to'!D21=Menus!C23,Menus!E23,Menus!E24)) -> 3
B22: Soil Carbon | E22: =IF(D22=Menus!C25,Menus!E25,IF('How to'!D22=Menus!C26,Menus!E26,Menus!E27)) -> 3
A23: Leakage is the shift of deforestation that was bound to happen in the project area to another area. This is plausible if mitigation projects are not implemented. Activity shifting leakage is when activities such as subsistence agriculture move. Market effects leakage is when deforestation/degradation due to commodities shifts to another region e.g. charcoal or timber.
A24: Leakage Risk | B24: Activity shifting | E24: =IF(D24=Menus!C28,Menus!E28, IF('How to'!D24=Menus!C29,Menus!E29,Menus!E30)) -> 10
B25: Market effects | E25: =IF(D25=Menus!C31,Menus!E31,IF(D25=Menus!C32,Menus!E32,Menus!E33)) -> 10
A26: This is one of the most important sections as tenure is sensitive and uncertain or contested tenure is a high risk. VCS and other standards are very strict on all components of tenure and demand transparency on tenure and robust contracts. Contested titles and boundaries could potentially fail a project, it thus has to be clarified from an early stage.
A27: Tenure/Rights Holders | B27: Single Entity | E27: =IF(D27="Y",Menus!E34,0) -> 0
B28: Multiple Entities | E28: =IF(D28="Y",Menus!E35,0) -> 0
B29: Unclear | E29: =IF(D29="Y",Menus!E36,0) -> 0
B30: Private title | E30: =IF(D30="Y",Menus!E37,0) -> 0
B31: Title deed sound (if applicable) | E31: =IF(D31="Y",Menus!E38,0) -> 0
B32: Landowner/Rights Holder Invitation | E32: =IF(D32="Y",Menus!E40,Menus!E41) -> 3
B33: Host country consent | E33: =IF(D33="Y",Menus!E42,0) -> 0
B34: Communal land | E34: =IF(D34="Y",Menus!E44,Menus!E45) -> 2
B35: Government land | E35: =IF('How to'!D35="Y",Menus!E46,Menus!E47) -> 2
A36: Use GIS and supplement as far as possible with feedback from locals. A lack of logistics can make a project non-viable.
A37: Logistics | B37: Road network | E37: =IF(D37=Menus!C48,Menus!E48,IF(D37=Menus!C49,Menus!E49,Menus!E50)) -> 2
B38: Airstrip | E38: =IF(D38="Y",Menus!E51,2) -> 2
B39: Accommodation and other infrastructure | E39: =IF(D39="Y",Menus!E53,Menus!E54) -> 2
B40: Water | E40: =IF(D40=Menus!C55,Menus!E55,IF(D40=Menus!C56,2,IF(D40=Menus!C57,Menus!E57,Menus!E58))) -> 9
B41: Electricity | E41: =IF(D41="Y",Menus!E59,0) -> 0
B42: Implementing partners? | E42: =IF(D42="Y",Menus!E60,Menus!E61) -> 5
A43: If the project does not satisfy additionality it fails under the VCS. The World Bank FCPF is proposing to do away with additionality for jurisdictional programmes if the jurisdiction has a credible baseline that ultimately will then qualify all projects as additional. The first question that needs to be asked to determine additionality is "what is the baseline?" That is, what is happening now? Deforestation through agriculture etc.? The project that will prevent this, is it simply "business as usual"?. Is the new project profitable? If yes, how profitable compared to other credible land uses? Are there other credible land uses other than the baseline or the project? If not, it is not additional. Are their barriers preventing project implementation or the baseline continuing? Use VCS Tool VT0001.
A44: Additionality | B44: Credible alternative land use | E44: =IF(D44="Y",Menus!E64,Menus!E65) -> 0
B45: Investment Analysis | C45: Project is profitable | E45: =IF(D45="Y",Menus!E66,Menus!E67) -> 5
B46: Barrier Analysis | C46: Credible barriers for implementation | E46: =IF(D46="Y",Menus!E68,Menus!E69) -> 0
C47: Baseline barriers | E47: =IF(D47="Y",Menus!E70,Menus!E71) -> 5
...

Sheet Area 1
A8: Site
A9: Category | B9: Sub-category | D9: Rating* | E9: Score
A10: Geospatial | B10: Topography | C10: Flat % | E10: =D10/100*Menus!E2 -> 0
C11: Hilly % | E11: =D11/100*Menus!E3 -> 0
C12: Mountainous % | E12: =D12/100*Menus!E4 -> 0
B13: Location relative to protected areas | C13: Border | E13: =IF(D13="Y",Menus!E5,Menus!E6) -> 5
B14: JNR Boundaries | C14: Within political boundary | E14: =IF(D14="Y",Menus!E8,Menus!E9) -> 5
B15: Size (ha) | E15: =IF(D15=Menus!C11,Menus!E11,IF(D15=Menus!C12,Menus!E12,Menus!E13)) -> 2
B16: Landsat Tiles | C16: Below | E16: =IF(D16="Y",Menus!E15,Menus!E14) -> 2
A17: Forest metrics | B17: Deforestation threat | E17: =IF(D17=Menus!C16,Menus!E16,IF('Area 1'!D17=Menus!C12,Menus!E12,Menus!E13)) -> 2
B18: Forest cover | E18: =IF(D18=Menus!C19,Menus!E19,IF(D18=Menus!C20,Menus!E20,Menus!E21)) -> 2
B19: Biomass Carbon density | E19: =IF(D19=Menus!C22,Menus!E22,IF('Area 1'!D19=Menus!C23,Menus!E23,Menus!E24)) -> 3
B20: Soil Carbon | E20: =IF(D20=Menus!C25,Menus!E25,IF('Area 1'!D20=Menus!C26,Menus!E26,Menus!E27)) -> 3
A21: Leakage Risk | B21: Activity shifting | E21: =IF(D21=Menus!C28,Menus!E28, IF('Area 1'!D21=Menus!C29,Menus!E29,Menus!E30)) -> 10
B22: Market effects | E22: =IF(D22=Menus!C31,Menus!E31,IF(D22=Menus!C32,Menus!E32,Menus!E33)) -> 10
A23: Tenure/Rights Holders | B23: Single Entity | E23: =IF(D23="Y",Menus!E34,0) -> 0
B24: Multiple Entities | E24: =IF(D24="Y",Menus!E35,0) -> 0
B25: Unclear | E25: =IF(D25="Y",Menus!E36,0) -> 0
B26: Private title | E26: =IF(D26="Y",Menus!E37,0) -> 0
B27: Title deed sound (if applicable) | E27: =IF(D27="Y",Menus!E38,0) -> 0
B28: Landowner/Rights Holder Invitation | E28: =IF(D28="Y",Menus!E40,Menus!E41) -> 3
B29: Host country consent | E29: =IF(D29="Y",Menus!E42,0) -> 0
B30: Communal land | E30: =IF(D30="Y",Menus!E44,Menus!E45) -> 2
B31: Government land | E31: =IF('Area 1'!D31="Y",Menus!E46,Menus!E47) -> 2
A32: Logistics | B32: Road network | E32: =IF(D32=Menus!C48,Menus!E48,IF(D32=Menus!C49,Menus!E49,Menus!E50)) -> 2
B33: Airstrip | E33: =IF(D33="Y",Menus!E51,2) -> 2
B34: Accommodation and other infrastructure | E34: =IF(D34="Y",Menus!E53,Menus!E54) -> 2
B35: Water | E35: =IF(D35=Menus!C55,Menus!E55,IF(D35=Menus!C56,2,IF(D35=Menus!C57,Menus!E57,Menus!E58))) -> 9
B36: Electricity | E36: =IF(D36="Y",Menus!E59,0) -> 0
B37: Implementing partners? | E37: =IF(D37="Y",Menus!E60,Menus!E61) -> 5
A38: Additionality | B38: Credible alternative land use | E38: =IF(D38="Y",Menus!E64,Menus!E65) -> 0
B39: Investment Analysis | C39: Project is profitable | E39: =IF(D39="Y",Menus!E66,Menus!E67) -> 5
B40: Barrier Analysis | C40: Credible barriers for implementation | E40: =IF(D40="Y",Menus!E68,Menus!E69) -> 0
C41: Baseline barriers | E41: =IF(D41="Y",Menus!E70,Menus!E71) -> 5
B42: Common practice analysis | C42: Project is common practice | E42: =IF(D42=Menus!E72,Menus!E72,Menus!E73) -> 5
A43: Non-permanence risk | B43: Boundary disputes | E43: =IF(D43="Y",Menus!E74,Menus!E75) -> 10
B44: Natural risks | E44: =IF(D44=Menus!E76,Menus!E76,Menus!E77) -> 5
B45: In country political risks | E45: =IF(D45="Y",Menus!E78,Menus!E79) -> 5
B46: Opportunity costs | E46: =IF(D46=Menus!C80,Menus!E80,IF(D46=Menus!C81,Menus!E81,Menus!E82)) -> 10
A47: Social benefits | B47: Benefits to poorest of poor? | E47: =IF(D47="Y",Menus!E83,2) -> 2
...

Sheet Sheet3

Sheet Sheet4

Sheet Sheet5

Sheet Sheet6

Sheet Sheet7

Sheet Sheet8
